2019-03-26 09:19:51,431 INFO  retry.RetryInvocationHandler RetryInvocationHandler.java:log:411 - java.io.EOFException: End of File Exception between local host is: "clnode034.clemson.cloudlab.us/130.127.133.43"; destination host is: "node-1-link-0":8020; : java.io.EOFException; For more details see:  http://wiki.apache.org/hadoop/EOFException, while invoking ClientNamenodeProtocolTranslatorPB.addBlock over node-1-link-0/10.10.1.4:8020. Trying to failover immediately.
2019-03-26 09:19:51,439 INFO  retry.RetryInvocationHandler RetryInvocationHandler.java:log:411 - org.apache.hadoop.ipc.RemoteException(org.apache.hadoop.ipc.StandbyException): Operation category READ is not supported in state standby. Visit https://s.apache.org/sbnn-error
	at org.apache.hadoop.hdfs.server.namenode.ha.StandbyState.checkOperation(StandbyState.java:88)
	at org.apache.hadoop.hdfs.server.namenode.NameNode$NameNodeHAContext.checkOperation(NameNode.java:1952)
	at org.apache.hadoop.hdfs.server.namenode.FSNamesystem.checkOperation(FSNamesystem.java:1423)
	at org.apache.hadoop.hdfs.server.namenode.FSNamesystem.getAdditionalBlock(FSNamesystem.java:2674)
	at org.apache.hadoop.hdfs.server.namenode.NameNodeRpcServer.addBlock(NameNodeRpcServer.java:875)
	at org.apache.hadoop.hdfs.protocolPB.ClientNamenodeProtocolServerSideTranslatorPB.addBlock(ClientNamenodeProtocolServerSideTranslatorPB.java:561)
	at org.apache.hadoop.hdfs.protocol.proto.ClientNamenodeProtocolProtos$ClientNamenodeProtocol$2.callBlockingMethod(ClientNamenodeProtocolProtos.java)
	at org.apache.hadoop.ipc.ProtobufRpcEngine$Server$ProtoBufRpcInvoker.call(ProtobufRpcEngine.java:523)
	at org.apache.hadoop.ipc.RPC$Server.call(RPC.java:991)
	at org.apache.hadoop.ipc.Server$RpcCall.run(Server.java:872)
	at org.apache.hadoop.ipc.Server$RpcCall.run(Server.java:818)
	at java.security.AccessController.doPrivileged(Native Method)
	at javax.security.auth.Subject.doAs(Subject.java:422)
	at org.apache.hadoop.security.UserGroupInformation.doAs(UserGroupInformation.java:1729)
	at org.apache.hadoop.ipc.Server$Handler.run(Server.java:2678)
, while invoking ClientNamenodeProtocolTranslatorPB.addBlock over node-0-link-0/10.10.1.1:8020 after 1 failover attempts. Trying to failover after sleeping for 1052ms.
2019-03-26 09:19:52,496 INFO  retry.RetryInvocationHandler RetryInvocationHandler.java:log:411 - java.net.ConnectException: Call From clnode034.clemson.cloudlab.us/130.127.133.43 to node-1-link-0:8020 failed on connection exception: java.net.ConnectException: Connection refused; For more details see:  http://wiki.apache.org/hadoop/ConnectionRefused, while invoking ClientNamenodeProtocolTranslatorPB.addBlock over node-1-link-0/10.10.1.4:8020 after 2 failover attempts. Trying to failover after sleeping for 1217ms.
2019-03-26 09:19:53,715 INFO  retry.RetryInvocationHandler RetryInvocationHandler.java:log:411 - org.apache.hadoop.ipc.RemoteException(org.apache.hadoop.ipc.StandbyException): Operation category READ is not supported in state standby. Visit https://s.apache.org/sbnn-error
	at org.apache.hadoop.hdfs.server.namenode.ha.StandbyState.checkOperation(StandbyState.java:88)
	at org.apache.hadoop.hdfs.server.namenode.NameNode$NameNodeHAContext.checkOperation(NameNode.java:1952)
	at org.apache.hadoop.hdfs.server.namenode.FSNamesystem.checkOperation(FSNamesystem.java:1423)
	at org.apache.hadoop.hdfs.server.namenode.FSNamesystem.getAdditionalBlock(FSNamesystem.java:2674)
	at org.apache.hadoop.hdfs.server.namenode.NameNodeRpcServer.addBlock(NameNodeRpcServer.java:875)
	at org.apache.hadoop.hdfs.protocolPB.ClientNamenodeProtocolServerSideTranslatorPB.addBlock(ClientNamenodeProtocolServerSideTranslatorPB.java:561)
	at org.apache.hadoop.hdfs.protocol.proto.ClientNamenodeProtocolProtos$ClientNamenodeProtocol$2.callBlockingMethod(ClientNamenodeProtocolProtos.java)
	at org.apache.hadoop.ipc.ProtobufRpcEngine$Server$ProtoBufRpcInvoker.call(ProtobufRpcEngine.java:523)
	at org.apache.hadoop.ipc.RPC$Server.call(RPC.java:991)
	at org.apache.hadoop.ipc.Server$RpcCall.run(Server.java:872)
	at org.apache.hadoop.ipc.Server$RpcCall.run(Server.java:818)
	at java.security.AccessController.doPrivileged(Native Method)
	at javax.security.auth.Subject.doAs(Subject.java:422)
	at org.apache.hadoop.security.UserGroupInformation.doAs(UserGroupInformation.java:1729)
	at org.apache.hadoop.ipc.Server$Handler.run(Server.java:2678)
, while invoking ClientNamenodeProtocolTranslatorPB.addBlock over node-0-link-0/10.10.1.1:8020 after 3 failover attempts. Trying to failover after sleeping for 4506ms.
2019-03-26 09:19:58,224 INFO  retry.RetryInvocationHandler RetryInvocationHandler.java:log:411 - java.net.ConnectException: Call From clnode034.clemson.cloudlab.us/130.127.133.43 to node-1-link-0:8020 failed on connection exception: java.net.ConnectException: Connection refused; For more details see:  http://wiki.apache.org/hadoop/ConnectionRefused, while invoking ClientNamenodeProtocolTranslatorPB.addBlock over node-1-link-0/10.10.1.4:8020 after 4 failover attempts. Trying to failover after sleeping for 6753ms.
2019-03-26 09:20:04,979 INFO  retry.RetryInvocationHandler RetryInvocationHandler.java:log:411 - java.net.ConnectException: Call From clnode034.clemson.cloudlab.us/130.127.133.43 to node-0-link-0:8020 failed on connection exception: java.net.ConnectException: Connection refused; For more details see:  http://wiki.apache.org/hadoop/ConnectionRefused, while invoking ClientNamenodeProtocolTranslatorPB.addBlock over node-0-link-0/10.10.1.1:8020 after 5 failover attempts. Trying to failover after sleeping for 17254ms.
2019-03-26 09:20:19,546 INFO  retry.RetryInvocationHandler RetryInvocationHandler.java:log:411 - java.net.ConnectException: Call From clnode034.clemson.cloudlab.us/130.127.133.43 to node-0-link-0:8020 failed on connection exception: java.net.ConnectException: Connection refused; For more details see:  http://wiki.apache.org/hadoop/ConnectionRefused, while invoking ClientNamenodeProtocolTranslatorPB.renewLease over node-0-link-0/10.10.1.1:8020. Trying to failover immediately.
2019-03-26 09:20:19,548 INFO  retry.RetryInvocationHandler RetryInvocationHandler.java:log:411 - java.net.ConnectException: Call From clnode034.clemson.cloudlab.us/130.127.133.43 to node-1-link-0:8020 failed on connection exception: java.net.ConnectException: Connection refused; For more details see:  http://wiki.apache.org/hadoop/ConnectionRefused, while invoking ClientNamenodeProtocolTranslatorPB.renewLease over node-1-link-0/10.10.1.4:8020 after 1 failover attempts. Trying to failover after sleeping for 513ms.
2019-03-26 09:20:20,062 INFO  retry.RetryInvocationHandler RetryInvocationHandler.java:log:411 - java.net.ConnectException: Call From clnode034.clemson.cloudlab.us/130.127.133.43 to node-0-link-0:8020 failed on connection exception: java.net.ConnectException: Connection refused; For more details see:  http://wiki.apache.org/hadoop/ConnectionRefused, while invoking ClientNamenodeProtocolTranslatorPB.renewLease over node-0-link-0/10.10.1.1:8020 after 2 failover attempts. Trying to failover after sleeping for 1030ms.
2019-03-26 09:20:21,094 INFO  retry.RetryInvocationHandler RetryInvocationHandler.java:log:411 - java.net.ConnectException: Call From clnode034.clemson.cloudlab.us/130.127.133.43 to node-1-link-0:8020 failed on connection exception: java.net.ConnectException: Connection refused; For more details see:  http://wiki.apache.org/hadoop/ConnectionRefused, while invoking ClientNamenodeProtocolTranslatorPB.renewLease over node-1-link-0/10.10.1.4:8020 after 3 failover attempts. Trying to failover after sleeping for 5736ms.
2019-03-26 09:20:22,234 WARN  retry.RetryInvocationHandler RetryInvocationHandler.java:failover:220 - A failover has occurred since the start of call #8 ClientNamenodeProtocolTranslatorPB.addBlock over node-1-link-0/10.10.1.4:8020
2019-03-26 09:20:22,236 INFO  retry.RetryInvocationHandler RetryInvocationHandler.java:log:411 - java.net.ConnectException: Call From clnode034.clemson.cloudlab.us/130.127.133.43 to node-1-link-0:8020 failed on connection exception: java.net.ConnectException: Connection refused; For more details see:  http://wiki.apache.org/hadoop/ConnectionRefused, while invoking ClientNamenodeProtocolTranslatorPB.addBlock over node-1-link-0/10.10.1.4:8020 after 6 failover attempts. Trying to failover after sleeping for 13853ms.
2019-03-26 09:20:26,832 INFO  retry.RetryInvocationHandler RetryInvocationHandler.java:log:411 - java.net.ConnectException: Call From clnode034.clemson.cloudlab.us/130.127.133.43 to node-0-link-0:8020 failed on connection exception: java.net.ConnectException: Connection refused; For more details see:  http://wiki.apache.org/hadoop/ConnectionRefused, while invoking ClientNamenodeProtocolTranslatorPB.renewLease over node-0-link-0/10.10.1.1:8020 after 4 failover attempts. Trying to failover after sleeping for 10184ms.
2019-03-26 09:20:36,089 WARN  retry.RetryInvocationHandler RetryInvocationHandler.java:failover:220 - A failover has occurred since the start of call #8 ClientNamenodeProtocolTranslatorPB.addBlock over node-0-link-0/10.10.1.1:8020
2019-03-26 09:20:36,091 INFO  retry.RetryInvocationHandler RetryInvocationHandler.java:log:411 - java.net.ConnectException: Call From clnode034.clemson.cloudlab.us/130.127.133.43 to node-0-link-0:8020 failed on connection exception: java.net.ConnectException: Connection refused; For more details see:  http://wiki.apache.org/hadoop/ConnectionRefused, while invoking ClientNamenodeProtocolTranslatorPB.addBlock over node-0-link-0/10.10.1.1:8020 after 7 failover attempts. Trying to failover after sleeping for 21750ms.
2019-03-26 09:20:37,018 INFO  retry.RetryInvocationHandler RetryInvocationHandler.java:log:411 - java.net.ConnectException: Call From clnode034.clemson.cloudlab.us/130.127.133.43 to node-1-link-0:8020 failed on connection exception: java.net.ConnectException: Connection refused; For more details see:  http://wiki.apache.org/hadoop/ConnectionRefused, while invoking ClientNamenodeProtocolTranslatorPB.renewLease over node-1-link-0/10.10.1.4:8020 after 5 failover attempts. Trying to failover after sleeping for 22169ms.
2019-03-26 09:20:57,842 WARN  retry.RetryInvocationHandler RetryInvocationHandler.java:failover:220 - A failover has occurred since the start of call #8 ClientNamenodeProtocolTranslatorPB.addBlock over node-1-link-0/10.10.1.4:8020
2019-03-26 09:20:57,844 INFO  retry.RetryInvocationHandler RetryInvocationHandler.java:log:411 - java.net.ConnectException: Call From clnode034.clemson.cloudlab.us/130.127.133.43 to node-1-link-0:8020 failed on connection exception: java.net.ConnectException: Connection refused; For more details see:  http://wiki.apache.org/hadoop/ConnectionRefused, while invoking ClientNamenodeProtocolTranslatorPB.addBlock over node-1-link-0/10.10.1.4:8020 after 8 failover attempts. Trying to failover after sleeping for 18064ms.
2019-03-26 09:20:59,191 INFO  retry.RetryInvocationHandler RetryInvocationHandler.java:log:411 - java.net.ConnectException: Call From clnode034.clemson.cloudlab.us/130.127.133.43 to node-0-link-0:8020 failed on connection exception: java.net.ConnectException: Connection refused; For more details see:  http://wiki.apache.org/hadoop/ConnectionRefused, while invoking ClientNamenodeProtocolTranslatorPB.renewLease over node-0-link-0/10.10.1.1:8020 after 6 failover attempts. Trying to failover after sleeping for 14775ms.
2019-03-26 09:21:13,968 INFO  retry.RetryInvocationHandler RetryInvocationHandler.java:log:411 - java.net.ConnectException: Call From clnode034.clemson.cloudlab.us/130.127.133.43 to node-1-link-0:8020 failed on connection exception: java.net.ConnectException: Connection refused; For more details see:  http://wiki.apache.org/hadoop/ConnectionRefused, while invoking ClientNamenodeProtocolTranslatorPB.renewLease over node-1-link-0/10.10.1.4:8020 after 7 failover attempts. Trying to failover after sleeping for 22307ms.
2019-03-26 09:21:15,908 WARN  retry.RetryInvocationHandler RetryInvocationHandler.java:failover:220 - A failover has occurred since the start of call #8 ClientNamenodeProtocolTranslatorPB.addBlock over node-1-link-0/10.10.1.4:8020
2019-03-26 09:21:15,910 INFO  retry.RetryInvocationHandler RetryInvocationHandler.java:log:411 - java.net.ConnectException: Call From clnode034.clemson.cloudlab.us/130.127.133.43 to node-1-link-0:8020 failed on connection exception: java.net.ConnectException: Connection refused; For more details see:  http://wiki.apache.org/hadoop/ConnectionRefused, while invoking ClientNamenodeProtocolTranslatorPB.addBlock over node-1-link-0/10.10.1.4:8020 after 9 failover attempts. Trying to failover after sleeping for 9104ms.
2019-03-26 09:21:25,017 INFO  retry.RetryInvocationHandler RetryInvocationHandler.java:log:411 - java.net.ConnectException: Call From clnode034.clemson.cloudlab.us/130.127.133.43 to node-0-link-0:8020 failed on connection exception: java.net.ConnectException: Connection refused; For more details see:  http://wiki.apache.org/hadoop/ConnectionRefused, while invoking ClientNamenodeProtocolTranslatorPB.addBlock over node-0-link-0/10.10.1.1:8020 after 10 failover attempts. Trying to failover after sleeping for 8327ms.
